<?xml version="1.0" ?>
<mujoco model="orcahand">
  <!-- eulerseq "XYZ" corresponds to URDF "rpy" -->
  <compiler angle="radian" eulerseq="XYZ" meshdir="meshes/right"/>
  <default>
    <mesh scale="0.001 0.001 0.001"/>
    <!-- Visual classes -->
    <default class="visual_base">
      <geom conaffinity="0" condim="1" contype="0" group="2" type="mesh"/>
      <default class="skin">
        <geom material="white"/>
      </default>
      <default class="bone">
        <geom material="black"/>
      </default>
    </default>
    <!-- Collision class -->
    <default class="collision">
      <geom conaffinity="1" condim="3" contype="1" group="1" material="invisible" type="mesh"/>
    </default>
    <!-- Joints -->
    <joint armature="0.001" damping="0.1" frictionloss="0.001" limited="true" margin="0.01" type="hinge"/>
    <position ctrllimited="true" forcelimited="true" forcerange="-1 1" kp="2.0"/>
  </default>
  <asset>
    <!-- Visual -->
    <mesh file="visual/visual_tower_main.stl" name="visual_tower_main_mesh"/>
    <mesh file="visual/visual_tower_hull.stl" name="visual_tower_hull_mesh"/>
    <mesh file="visual/visual_tower_text.stl" name="visual_tower_text_mesh"/>
    <mesh file="visual/visual_tower_fans.stl" name="visual_tower_fans_mesh"/>
    <mesh file="visual/visual_tower_u2d2.stl" name="visual_tower_u2d2_mesh"/>
    <mesh file="visual/visual_tower_camera.stl" name="visual_tower_camera_mesh"/>
    <mesh file="visual/visual_palm.stl" name="visual_palm_mesh"/>
    <mesh file="visual/visual_thumb_mp.stl" name="visual_thumb_mp_mesh"/>
    <mesh file="visual/visual_thumb_pp.stl" name="visual_thumb_pp_mesh"/>
    <mesh file="visual/visual_thumb_ip.stl" name="visual_thumb_ip_mesh"/>
    <mesh file="visual/visual_thumb_dp.stl" name="visual_thumb_dp_mesh"/>
    <mesh file="visual/visual_index_mp.stl" name="visual_index_mp_mesh"/>
    <mesh file="visual/visual_index_pp.stl" name="visual_index_pp_mesh"/>
    <mesh file="visual/visual_index_ip.stl" name="visual_index_ip_mesh"/>
    <mesh file="visual/visual_middle_mp.stl" name="visual_middle_mp_mesh"/>
    <mesh file="visual/visual_middle_pp.stl" name="visual_middle_pp_mesh"/>
    <mesh file="visual/visual_middle_ip.stl" name="visual_middle_ip_mesh"/>
    <mesh file="visual/visual_ring_mp.stl" name="visual_ring_mp_mesh"/>
    <mesh file="visual/visual_ring_pp.stl" name="visual_ring_pp_mesh"/>
    <mesh file="visual/visual_ring_ip.stl" name="visual_ring_ip_mesh"/>
    <mesh file="visual/visual_pinky_mp.stl" name="visual_pinky_mp_mesh"/>
    <mesh file="visual/visual_pinky_pp.stl" name="visual_pinky_pp_mesh"/>
    <mesh file="visual/visual_pinky_ip.stl" name="visual_pinky_ip_mesh"/>
    <mesh file="visual/visual_palm_skin.stl" name="visual_palm_skin_mesh"/>
    <mesh file="visual/visual_thumb_ip_skin.stl" name="visual_thumb_ip_skin_mesh"/>
    <mesh file="visual/visual_thumb_dp_skin.stl" name="visual_thumb_dp_skin_mesh"/>
    <mesh file="visual/visual_index_pp_skin.stl" name="visual_index_pp_skin_mesh"/>
    <mesh file="visual/visual_index_ip_skin.stl" name="visual_index_ip_skin_mesh"/>
    <mesh file="visual/visual_middle_pp_skin.stl" name="visual_middle_pp_skin_mesh"/>
    <mesh file="visual/visual_middle_ip_skin.stl" name="visual_middle_ip_skin_mesh"/>
    <mesh file="visual/visual_ring_pp_skin.stl" name="visual_ring_pp_skin_mesh"/>
    <mesh file="visual/visual_ring_ip_skin.stl" name="visual_ring_ip_skin_mesh"/>
    <mesh file="visual/visual_pinky_pp_skin.stl" name="visual_pinky_pp_skin_mesh"/>
    <mesh file="visual/visual_pinky_ip_skin.stl" name="visual_pinky_ip_skin_mesh"/>
    <!-- Collision -->
    <mesh file="collision/collision_tower_main.stl" name="collision_tower_main_mesh"/>
    <mesh file="collision/collision_tower_hull.stl" name="collision_tower_hull_mesh"/>
    <mesh file="collision/collision_tower_text.stl" name="collision_tower_text_mesh"/>
    <mesh file="collision/collision_tower_fans.stl" name="collision_tower_fans_mesh"/>
    <mesh file="collision/collision_tower_u2d2.stl" name="collision_tower_u2d2_mesh"/>
    <mesh file="collision/collision_tower_camera.stl" name="collision_tower_camera_mesh"/>
    <mesh file="collision/collision_palm.stl" name="collision_palm_mesh"/>
    <mesh file="collision/collision_thumb_mp.stl" name="collision_thumb_mp_mesh"/>
    <mesh file="collision/collision_thumb_pp.stl" name="collision_thumb_pp_mesh"/>
    <mesh file="collision/collision_thumb_ip.stl" name="collision_thumb_ip_mesh"/>
    <mesh file="collision/collision_thumb_dp.stl" name="collision_thumb_dp_mesh"/>
    <mesh file="collision/collision_index_mp.stl" name="collision_index_mp_mesh"/>
    <mesh file="collision/collision_index_pp.stl" name="collision_index_pp_mesh"/>
    <mesh file="collision/collision_index_ip.stl" name="collision_index_ip_mesh"/>
    <mesh file="collision/collision_middle_mp.stl" name="collision_middle_mp_mesh"/>
    <mesh file="collision/collision_middle_pp.stl" name="collision_middle_pp_mesh"/>
    <mesh file="collision/collision_middle_ip.stl" name="collision_middle_ip_mesh"/>
    <mesh file="collision/collision_ring_mp.stl" name="collision_ring_mp_mesh"/>
    <mesh file="collision/collision_ring_pp.stl" name="collision_ring_pp_mesh"/>
    <mesh file="collision/collision_ring_ip.stl" name="collision_ring_ip_mesh"/>
    <mesh file="collision/collision_pinky_mp.stl" name="collision_pinky_mp_mesh"/>
    <mesh file="collision/collision_pinky_pp.stl" name="collision_pinky_pp_mesh"/>
    <mesh file="collision/collision_pinky_ip.stl" name="collision_pinky_ip_mesh"/>
    <mesh file="collision/collision_palm_skin.stl" name="collision_palm_skin_mesh"/>
    <mesh file="collision/collision_thumb_ip_skin.stl" name="collision_thumb_ip_skin_mesh"/>
    <mesh file="collision/collision_thumb_dp_skin.stl" name="collision_thumb_dp_skin_mesh"/>
    <mesh file="collision/collision_index_pp_skin.stl" name="collision_index_pp_skin_mesh"/>
    <mesh file="collision/collision_index_ip_skin.stl" name="collision_index_ip_skin_mesh"/>
    <mesh file="collision/collision_middle_pp_skin.stl" name="collision_middle_pp_skin_mesh"/>
    <mesh file="collision/collision_middle_ip_skin.stl" name="collision_middle_ip_skin_mesh"/>
    <mesh file="collision/collision_ring_pp_skin.stl" name="collision_ring_pp_skin_mesh"/>
    <mesh file="collision/collision_ring_ip_skin.stl" name="collision_ring_ip_skin_mesh"/>
    <mesh file="collision/collision_pinky_pp_skin.stl" name="collision_pinky_pp_skin_mesh"/>
    <mesh file="collision/collision_pinky_ip_skin.stl" name="collision_pinky_ip_skin_mesh"/>
    <!-- Materials -->
    <material name="white" rgba="1 1 1 1" shininess="0.5" specular="0.1"/>
    <material name="black" rgba="0.25 0.25 0.25 1" shininess="0.2" specular="0.05"/>
    <material name="invisible" rgba="1 1 1 0" shininess="0" specular="0"/>
  </asset>
  <worldbody>
    <body name="root">
      <!-- ======== -->
      <!-- | BASE | -->
      <!-- ======== -->
      <!-- Body: tower -->
      <body euler="0.0 0.0 0.0" name="tower" pos="-0.04 0.0 0.04975">
        <inertial diaginertia="0.00209359 0.0018456 0.00136054" euler="0.21624 0.00268 0.04786" mass="1.1" pos="0.04263 0.00274 0.01558"/>
        <!-- Main -->
        <geom class="bone" mesh="visual_tower_main_mesh"/>
        <geom class="collision" mesh="collision_tower_main_mesh"/>
        <!-- Hull -->
        <geom class="bone" mesh="visual_tower_hull_mesh"/>
        <geom class="collision" mesh="collision_tower_hull_mesh"/>
        <!-- Text -->
        <geom class="skin" mesh="visual_tower_text_mesh"/>
        <geom class="collision" mesh="collision_tower_text_mesh"/>
        <!-- Fans -->
        <geom class="bone" mesh="visual_tower_fans_mesh"/>
        <geom class="collision" mesh="collision_tower_fans_mesh"/>
        <!-- U2D2 Board -->
        <geom class="bone" mesh="visual_tower_u2d2_mesh"/>
        <geom class="collision" mesh="collision_tower_u2d2_mesh"/>
        <!-- Camera Mount -->
        <geom class="bone" mesh="visual_tower_camera_mesh"/>
        <geom class="collision" mesh="collision_tower_camera_mesh"/>
        <!-- Body: palm -->
        <body euler="0.0 -0.0 0.0" name="palm" pos="0.03863 0.00144 0.14359">
          <inertial diaginertia="1.612e-05 1.151e-05 6.72e-06" euler="1.67519 0.0475 1.55556" mass="0.0257" pos="0.00193 -0.00052 -0.00664"/>
          <joint axis="1.0 0.0 -0.0" name="wrist" pos="0.002 -0.00144 -0.03872" range="-0.6736 0.8972" ref="-0.15"/>
          <!-- Bone -->
          <geom class="bone" mesh="visual_palm_mesh"/>
          <geom class="collision" mesh="collision_palm_mesh"/>
          <!-- Skin -->
          <geom class="skin" mesh="visual_palm_skin_mesh"/>
          <geom class="collision" mesh="collision_palm_skin_mesh"/>
          <!-- ========= -->
          <!-- | THUMB | -->
          <!-- ========= -->
          <!-- Body: thump_mp -->
          <body euler="0.53857 -0.05595 -1.27047" name="thumb_mp" pos="-0.02821 0.01777 -0.01321">
            <inertial diaginertia="8.4e-07 6.6e-07 2.7e-07" euler="0.0 0.01625 0.0" mass="0.00586" pos="0.00247 0.0 0.004"/>
            <joint axis="0.0 -0.0 -1.0" name="thumb_mcp" pos="-0.0 -0.0 -0.0" range="-0.87266 0.87266" ref="0.0"/>
            <!-- Bone -->
            <geom class="bone" mesh="visual_thumb_mp_mesh"/>
            <geom class="collision" mesh="collision_thumb_mp_mesh"/>
            <!-- Body: thumb_pp -->
            <body euler="-1.22173 -0.0 -0.0" name="thumb_pp" pos="-0.03 0.0 0.0">
              <inertial diaginertia="7.5e-07 7.1e-07 3e-07" euler="1.5708 0.77392 1.5708" mass="0.00655" pos="0.01848 1e-05 2e-05"/>
              <joint axis="0.0 0.34202 0.93969" name="thumb_abd" pos="0.03 0.0 -0.0" range="-1.08211 0.0" ref="-0.73304"/>
              <!-- Bone -->
              <geom class="bone" mesh="visual_thumb_pp_mesh"/>
              <geom class="collision" mesh="collision_thumb_pp_mesh"/>
              <!-- Body: thumb_ip -->
              <body euler="3.14159 1.5708 0.0" name="thumb_ip" pos="-0.0 0.0 -0.0">
                <inertial diaginertia="1.7e-06 1.64e-06 5.9e-07" euler="0.00037 0.03263 0.00034" mass="0.01402" pos="0.00135 2e-05 0.01383"/>
                <joint axis="0.0 -1.0 -0.0" name="thumb_pip" pos="0.0 -0.0 0.0" range="-0.7944 1.23" ref="-0.58496"/>
                <!-- Bone -->
                <geom class="bone" mesh="visual_thumb_ip_mesh"/>
                <geom class="collision" mesh="collision_thumb_ip_mesh"/>
                <!-- Skin -->
                <geom class="skin" mesh="visual_thumb_ip_skin_mesh"/>
                <geom class="collision" mesh="collision_thumb_ip_skin_mesh"/>
                <!-- Body: thumb_dp -->
                <body euler="0.0 0.0 0.0" name="thumb_dp" pos="0.0005 -0.0 0.033">
                  <inertial diaginertia="1.4e-06 1.37e-06 4.4e-07" euler="0.00075 0.08211 0.00013" mass="0.0132" pos="0.00233 1e-05 0.01133"/>
                  <joint axis="-0.0 -1.0 0.0" name="thumb_dip" pos="-0.0 -0.0 0.0" range="-0.85384 1.45" ref="-0.50477"/>
                  <!-- Bone -->
                  <geom class="bone" mesh="visual_thumb_dp_mesh"/>
                  <geom class="collision" mesh="collision_thumb_dp_mesh"/>
                  <!-- Skin -->
                  <geom class="skin" mesh="visual_thumb_dp_skin_mesh" euler="0.0 0.52 0.0" pos="-0.009 0 -0.011"/>
                  <geom class="collision" mesh="collision_thumb_dp_skin_mesh" euler="0.0 0.52 0.0" pos="-0.009 0 -0.011"/>
                </body>
              </body>
            </body>
          </body>
          <!-- ========= -->
          <!-- | INDEX | -->
          <!-- ========= -->
          <!-- Body: index_mp -->
          <body euler="1.6067 1.13552 -0.05339" name="index_mp" pos="-0.03251 0.00235 0.0433">
            <inertial diaginertia="3.4e-07 3.1e-07 2e-07" euler="3.14159 -1.5708 0.0" mass="0.00498" pos="0.01155 -0.0 -4e-05"/>
            <joint axis="0.0 0.0 -1.0" name="index_abd" pos="0.02 0.0 0.0" range="-1.04577 0.24577" ref="-0.4"/>
            <!-- Bone -->
            <geom class="bone" mesh="visual_index_mp_mesh"/>
            <geom class="collision" mesh="collision_index_mp_mesh"/>
            <!-- Body: index_pp -->
            <body euler="0.0 -1.5708 0.0" name="index_pp" pos="0.0 -0.0 0.0">
              <inertial diaginertia="2.39e-06 2.31e-06 7.1e-07" euler="0.00034 0.02055 0.00038" mass="0.0165" pos="0.00135 2e-05 0.01637"/>
              <joint axis="0.0 -1.0 0.0" name="index_mcp" pos="0.0 0.0 -0.0" range="-0.34907 1.65806"/>
              <!-- Bone -->
              <geom class="bone" mesh="visual_index_pp_mesh"/>
              <geom class="collision" mesh="collision_index_pp_mesh"/>
              <!-- Skin -->
              <geom class="skin" mesh="visual_index_pp_skin_mesh"/>
              <geom class="collision" mesh="collision_index_pp_skin_mesh"/>
              <!-- Body: index_ip -->
              <body euler="0.0 0.0 -0.0" name="index_ip" pos="0.0005 0.0 0.038">
                <inertial diaginertia="2.08e-06 2.06e-06 5.4e-07" euler="-0.00042 -0.18549 0.0044" mass="0.01521" pos="0.00071 1e-05 0.01929"/>
                <joint axis="0.0 -1.0 0.0" name="index_pip" pos="-0.0 0.0 0.0" range="-0.34907 1.88496"/>
                <!-- Bone -->
                <geom class="bone" mesh="visual_index_ip_mesh"/>
                <geom class="collision" mesh="collision_index_ip_mesh"/>
                <!-- Skin -->
                <geom class="skin" mesh="visual_index_ip_skin_mesh"/>
                <geom class="collision" mesh="collision_index_ip_skin_mesh"/>
              </body>
            </body>
          </body>
          <!-- ========== -->
          <!-- | MIDDLE | -->
          <!-- ========== -->
          <!-- Body: middle_mp -->
          <body euler="1.5708 1.5708 0.0" name="middle_mp" pos="-0.0 0.0 0.05">
            <inertial diaginertia="3.4e-07 3.1e-07 2e-07" euler="3.14159 -1.5708 0.0" mass="0.00498" pos="0.01155 -0.0 -4e-05"/>
            <joint axis="0.0 -0.0 -1.0" name="middle_abd" pos="0.02 -0.0 0.0" range="-0.64577 0.64577"/>
            <!-- Bone -->
            <geom class="bone" mesh="visual_middle_mp_mesh"/>
            <geom class="collision" mesh="collision_middle_mp_mesh"/>
            <!-- Body: middle_pp -->
            <body euler="0.0 -1.5708 0.0" name="middle_pp" pos="0.0 0.0 0.0">
              <inertial diaginertia="3.78e-06 3.69e-06 8.9e-07" euler="-3e-05 0.01386 0.0006" mass="0.02006" pos="0.00144 2e-05 0.02021"/>
              <joint axis="0.0 -1.0 -0.0" name="middle_mcp" pos="0.0 0.0 0.0" range="-0.34907 1.58825"/>
              <!-- Bone -->
              <geom class="bone" mesh="visual_middle_pp_mesh"/>
              <geom class="collision" mesh="collision_middle_pp_mesh"/>
              <!-- Skin -->
              <geom class="skin" mesh="visual_middle_pp_skin_mesh"/>
              <geom class="collision" mesh="collision_middle_pp_skin_mesh"/>
              <!-- Body: middle_ip -->
              <body euler="0.0 0.0 0.0" name="middle_ip" pos="0.0005 -0.0 0.046">
                <inertial diaginertia="2.08e-06 2.06e-06 5.4e-07" euler="-0.00042 -0.18549 0.0044" mass="0.01521" pos="0.00071 1e-05 0.01929"/>
                <joint axis="0.0 -1.0 -0.0" name="middle_pip" pos="-0.0 -0.0 0.0" range="-0.34907 1.8675"/>
                <!-- Bone -->
                <geom class="bone" mesh="visual_middle_ip_mesh"/>
                <geom class="collision" mesh="collision_middle_ip_mesh"/>
                <!-- Skin -->
                <geom class="skin" mesh="visual_middle_ip_skin_mesh"/>
                <geom class="collision" mesh="collision_middle_ip_skin_mesh"/>
              </body>
            </body>
          </body>
          <!-- ======== -->
          <!-- | RING | -->
          <!-- ======== -->
          <!-- Body: ring_mp -->
          <body euler="-1.53597 1.30836 -3.05441" name="ring_mp" pos="0.02669 0.00199 0.04014">
            <inertial diaginertia="3.4e-07 3.1e-07 2e-07" euler="3.14159 -1.5708 0.0" mass="0.00498" pos="0.01155 -0.0 -4e-05"/>
            <joint axis="0.0 -0.0 -1.0" name="ring_abd" pos="0.02 -0.0 0.0" range="-0.47577 0.80577" ref="0.17"/>
            <!-- Bone -->
            <geom class="bone" mesh="visual_ring_mp_mesh"/>
            <geom class="collision" mesh="collision_ring_mp_mesh"/>
            <!-- Body: ring_pp -->
            <body euler="0.0 -1.5708 0.0" name="ring_pp" pos="-0.0 0.0 -0.0">
              <inertial diaginertia="3.78e-06 3.69e-06 8.9e-07" euler="-3e-05 0.01386 0.0006" mass="0.02006" pos="0.00144 2e-05 0.02021"/>
              <joint axis="-0.0 -1.0 0.0" name="ring_mcp" pos="-0.0 0.0 0.0" range="-0.34907 1.58825"/>
              <!-- Bone -->
              <geom class="bone" mesh="visual_ring_pp_mesh"/>
              <geom class="collision" mesh="collision_ring_pp_mesh"/>
              <!-- Skin -->
              <geom class="skin" mesh="visual_ring_pp_skin_mesh"/>
              <geom class="collision" mesh="collision_ring_pp_skin_mesh"/>
              <!-- Body: ring_ip -->
              <body euler="-0.0 0.0 -0.0" name="ring_ip" pos="0.0005 -0.0 0.046">
                <inertial diaginertia="2.08e-06 2.06e-06 5.4e-07" euler="-0.00042 -0.18549 0.0044" mass="0.01521" pos="0.00071 1e-05 0.01929"/>
                <joint axis="-0.0 -1.0 0.0" name="ring_pip" pos="-0.0 0.0 0.0" range="-0.34907 1.8675"/>
                <!-- Bone -->
                <geom class="bone" mesh="visual_ring_ip_mesh"/>
                <geom class="collision" mesh="collision_ring_ip_mesh"/>
                <!-- Skin -->
                <geom class="skin" mesh="visual_ring_ip_skin_mesh"/>
                <geom class="collision" mesh="collision_ring_ip_skin_mesh"/>
              </body>
            </body>
          </body>
          <!-- ========= -->
          <!-- | PINKY | -->
          <!-- ========= -->
          <!-- Body: pinky_mp -->
          <body euler="-1.49694 0.86149 -2.88373" name="pinky_mp" pos="0.05518 0.00831 0.02242">
            <inertial diaginertia="3.4e-07 3.1e-07 2e-07" euler="3.14159 -1.5708 0.0" mass="0.00498" pos="0.01155 -0.0 -4e-05"/>
            <joint axis="-0.0 -0.0 -1.0" name="pinky_abd" pos="0.02 -0.0 -0.0" range="-0.12244 1.1691" ref="0.52333"/>
            <!-- Bone -->
            <geom class="bone" mesh="visual_pinky_mp_mesh"/>
            <geom class="collision" mesh="collision_pinky_mp_mesh"/>
            <!-- Body: pinky_pp -->
            <body euler="0.0 -1.5708 0.0" name="pinky_pp" pos="0.0 0.0 0.0">
              <inertial diaginertia="1.7e-06 1.64e-06 5.9e-07" euler="0.00037 0.03263 0.00034" mass="0.01402" pos="0.00135 2e-05 0.01383"/>
              <joint axis="0.0 -1.0 -0.0" name="pinky_mcp" pos="-0.0 -0.0 0.0" range="-0.34907 1.71042"/>
              <!-- Bone -->
              <geom class="bone" mesh="visual_pinky_pp_mesh"/>
              <geom class="collision" mesh="collision_pinky_pp_mesh"/>
              <!-- Skin -->
              <geom class="skin" mesh="visual_pinky_pp_skin_mesh"/>
              <geom class="collision" mesh="collision_pinky_pp_skin_mesh"/>
              <!-- Body: pinky_ip -->
              <body euler="-0.0 -0.0 0.0" name="pinky_ip" pos="0.0005 0.0 0.033">
                <inertial diaginertia="2.08e-06 2.06e-06 5.4e-07" euler="-0.00042 -0.18549 0.0044" mass="0.01521" pos="0.00071 1e-05 0.01929"/>
                <joint axis="0.0 -1.0 0.0" name="pinky_pip" pos="-0.0 -0.0 -0.0" range="-0.34907 1.88496"/>
                <!-- Bone -->
                <geom class="bone" mesh="visual_pinky_ip_mesh"/>
                <geom class="collision" mesh="collision_pinky_ip_mesh"/>
                <!-- Skin -->
                <geom class="skin" mesh="visual_pinky_ip_skin_mesh"/>
                <geom class="collision" mesh="collision_pinky_ip_skin_mesh"/>
              </body>
            </body>
          </body>
        </body>
      </body>
    </body>
  </worldbody>
  <actuator>
    <!-- Base -->
    <position ctrlrange="-0.6736 0.8972" joint="wrist" name="wrist_actuator"/>
    <!-- Thumb -->
    <position ctrlrange="-0.87266 0.87266" joint="thumb_mcp" name="thumb_mcp_actuator"/>
    <position ctrlrange="-1.08211 0.0" joint="thumb_abd" name="thumb_abd_actuator"/>
    <position ctrlrange="-0.7944 1.23" joint="thumb_pip" name="thumb_pip_actuator"/>
    <position ctrlrange="-0.85384 1.45" joint="thumb_dip" name="thumb_dip_actuator"/>
    <!-- Index -->
    <position ctrlrange="-1.04577 0.24577" joint="index_abd" name="index_abd_actuator"/>
    <position ctrlrange="-0.34907 1.65806" joint="index_mcp" name="index_mcp_actuator"/>
    <position ctrlrange="-0.34907 1.88496" joint="index_pip" name="index_pip_actuator"/>
    <!-- Middle -->
    <position ctrlrange="-0.64577 0.64577" joint="middle_abd" name="middle_abd_actuator"/>
    <position ctrlrange="-0.34907 1.58825" joint="middle_mcp" name="middle_mcp_actuator"/>
    <position ctrlrange="-0.34907 1.8675" joint="middle_pip" name="middle_pip_actuator"/>
    <!-- Ring -->
    <position ctrlrange="-0.47577 0.80577" joint="ring_abd" name="ring_abd_actuator"/>
    <position ctrlrange="-0.34907 1.58825" joint="ring_mcp" name="ring_mcp_actuator"/>
    <position ctrlrange="-0.34907 1.8675" joint="ring_pip" name="ring_pip_actuator"/>
    <!-- Pinky -->
    <position ctrlrange="-0.12244 1.1691" joint="pinky_abd" name="pinky_abd_actuator"/>
    <position ctrlrange="-0.34907 1.71042" joint="pinky_mcp" name="pinky_mcp_actuator"/>
    <position ctrlrange="-0.34907 1.88496" joint="pinky_pip" name="pinky_pip_actuator"/>
  </actuator>
  <contact>
    <!-- Base -->
    <exclude body1="root" body2="tower"/>
    <exclude body1="tower" body2="palm"/>
    <!-- Thumb -->
    <exclude body1="palm" body2="thumb_mp"/>
    <exclude body1="thumb_mp" body2="thumb_pp"/>
    <exclude body1="thumb_pp" body2="thumb_ip"/>
    <exclude body1="thumb_ip" body2="thumb_dp"/>
    <!-- Index -->
    <exclude body1="palm" body2="index_mp"/>
    <exclude body1="index_mp" body2="index_pp"/>
    <exclude body1="index_pp" body2="index_ip"/>
    <!-- Middle -->
    <exclude body1="palm" body2="middle_mp"/>
    <exclude body1="middle_mp" body2="middle_pp"/>
    <exclude body1="middle_pp" body2="middle_ip"/>
    <!-- Ring -->
    <exclude body1="palm" body2="ring_mp"/>
    <exclude body1="ring_mp" body2="ring_pp"/>
    <exclude body1="ring_pp" body2="ring_ip"/>
    <!-- Pinky -->
    <exclude body1="palm" body2="pinky_mp"/>
    <exclude body1="pinky_mp" body2="pinky_pp"/>
    <exclude body1="pinky_pp" body2="pinky_ip"/>
    <!-- For stability -->
    <exclude body1="palm" body2="thumb_pp"/>
  </contact>
</mujoco>
